# 越界异常 `out_of_range`

```cpp

try {

  // xcode 没崩溃, 但是 啥都不打印

// cout << s[100] << endl;

  // 这个会报异常

 cout << s.at(100) << endl;

 } catch (out_of_range &ex) {

 cout << ex.what() << endl;

 cout << "at 越界" << endl;

 }

```
